<?xml version="1.0" ?>
<!-- =================================================================================== -->
<!-- |    This document was autogenerated by xacro from /home/pengbin/arm_ws/src/xarm_ros/xarm_description/urdf/xarm_device.urdf.xacro | -->
<!-- |    EDITING THIS FILE BY HAND IS NOT RECOMMENDED                                 | -->
<!-- =================================================================================== -->
<robot name="xarm5" xmlns:xacro="http://www.ros.org/wiki/xacro" >

    <!-- Insert at the beginning of xarm_device_macro.xacro -->
    <material name="Black">
        <color rgba="0.0 0.0 0.0 1.0" />
    </material>
    <material name="Red">
        <color rgba="0.8 0.0 0.0 1.0" />
    </material>
    <material name="White">
        <color rgba="1.0 1.0 1.0 1.0" />
    </material>
    <material name="Silver">
        <color rgba="0.753 0.753 0.753 1.0" />
    </material>

    <!-- camera -->
    <xacro:d435i_urdf prefix="camera"/>
    <joint name="realsence_frame_joint" type="fixed">
        <origin rpy="0 0.0 0.0" xyz="-1.0 0.0 1" />
        <parent link="link_base"/>
        <child link="camera_link"/>
    </joint>



    <link name="world" />
    <joint name="world_joint" type="fixed">
        <parent link="world" />
        <child link="link_base" />
        <origin rpy="0 0 0" xyz="0 0 0" />
    </joint>
    <link name="link_base">
        <inertial>
            <origin rpy="0 0 0" xyz="-0.00218 -0.00023 0.08604" />
            <mass value="1.95" />
            <inertia ixx="0.004805" ixy="-8.33E-06" ixz="0.00026847" iyy="0.0050349" iyz="7.23E-06" izz="0.0025418" />
        </inertial>
        <visual>
            <geometry>
                <mesh filename="package://xarm_description/meshes/xarm5/visual/base_link.STL" />
            </geometry>
            <origin rpy="0 0 0" xyz="0 0 0" />
            <material name="White" />
        </visual>
        <collision>
            <geometry>
                <mesh filename="package://xarm_description/meshes/xarm5/visual/base_link.STL" />
            </geometry>
            <origin rpy="0 0 0" xyz="0 0 0" />
        </collision>
    </link>
    <link name="link1">
        <inertial>
            <origin rpy="0 0 0" xyz="0.00013 0.0294 -0.01239" />
            <mass value="2.3849" />
            <inertia ixx="0.005705" ixy="-1.056e-05" ixz="2.642e-05" iyy="0.00489488" iyz="0.000890795" izz="0.00334846" />
        </inertial>
        <visual>
            <geometry>
                <mesh filename="package://xarm_description/meshes/xarm5/visual/link1.STL" />
            </geometry>
            <origin rpy="0 0 0" xyz="0 0 0" />
            <material name="White" />
        </visual>
        <collision>
            <geometry>
                <mesh filename="package://xarm_description/meshes/xarm5/visual/link1.STL" />
            </geometry>
            <origin rpy="0 0 0" xyz="0 0 0" />
        </collision>
    </link>
    <joint name="joint1" type="revolute">
        <origin rpy="0 0 0" xyz="0 0 0.267" />
        <parent link="link_base" />
        <child link="link1" />
        <axis xyz="0 0 1" />
        <limit effort="50" lower="-6.283185307179586" upper="6.283185307179586" velocity="3.14" />
        <dynamics damping="10" friction="1" />
    </joint>
    <link name="link2">
        <inertial>
            <origin rpy="0 0 0" xyz="0.03788 -0.2254 0.03447" />
            <mass value="2.164" />
            <inertia ixx="0.0278053" ixy="-0.0048865" ixz="-0.000656695" iyy="0.00551739" iyz="0.00466808" izz="0.02692536" />
        </inertial>
        <visual>
            <geometry>
                <mesh filename="package://xarm_description/meshes/xarm5/visual/link2.STL" />
            </geometry>
            <origin rpy="0 0 0" xyz="0 0 0" />
            <material name="White" />
        </visual>
        <collision>
            <geometry>
                <mesh filename="package://xarm_description/meshes/xarm5/visual/link2.STL" />
            </geometry>
            <origin rpy="0 0 0" xyz="0 0 0" />
        </collision>
    </link>
    <joint name="joint2" type="revolute">
        <origin rpy="-1.5708 0 0" xyz="0 0 0" />
        <parent link="link1" />
        <child link="link2" />
        <axis xyz="0 0 1" />
        <limit effort="50" lower="-2.059" upper="2.0944" velocity="3.14" />
        <dynamics damping="10" friction="1" />
    </joint>
    <link name="link3">
        <inertial>
            <origin rpy="0 0 0" xyz="0.06883 0.22985 0.00102" />
            <mass value="2.121" />
            <inertia ixx="0.0373639" ixy="0.00417385" ixz="-0.00143647" iyy="0.0058447" iyz="-0.0075398" izz="0.0359236" />
        </inertial>
        <visual>
            <geometry>
                <mesh filename="package://xarm_description/meshes/xarm5/visual/link3.STL" />
            </geometry>
            <origin rpy="0 0 0" xyz="0 0 0" />
            <material name="White" />
        </visual>
        <collision>
            <geometry>
                <mesh filename="package://xarm_description/meshes/xarm5/visual/link3.STL" />
            </geometry>
            <origin rpy="0 0 0" xyz="0 0 0" />
        </collision>
    </link>
    <joint name="joint3" type="revolute">
        <origin rpy="0 0 0" xyz="0.0535 -0.2845 0" />
        <parent link="link2" />
        <child link="link3" />
        <axis xyz="0 0 1" />
        <limit effort="30" lower="-3.927" upper="0.19198" velocity="3.14" />
        <dynamics damping="5" friction="1" />
    </joint>
    <link name="link4">
        <inertial>
            <origin rpy="0 0 0" xyz="0.06489 0.03122 0.00319" />
            <mass value="1.3169" />
            <inertia ixx="0.00144315" ixy="0.000455133" ixz="-0.000291878" iyy="0.0018275" iyz="-0.000132545" izz="0.00231563" />
        </inertial>
        <visual>
            <geometry>
                <mesh filename="package://xarm_description/meshes/xarm5/visual/link4.STL" />
            </geometry>
            <origin rpy="0 0 0" xyz="0 0 0" />
            <material name="White" />
        </visual>
        <collision>
            <geometry>
                <mesh filename="package://xarm_description/meshes/xarm5/visual/link4.STL" />
            </geometry>
            <origin rpy="0 0 0" xyz="0 0 0" />
        </collision>
    </link>
    <joint name="joint4" type="revolute">
        <origin rpy="0 0 0" xyz="0.0775 0.3425 0" />
        <parent link="link3" />
        <child link="link4" />
        <axis xyz="0 0 1" />
        <limit effort="20" lower="-1.69297" upper="3.141592653589793" velocity="3.14" />
        <dynamics damping="3" friction="1" />
    </joint>
    <link name="link5">
        <inertial>
            <origin rpy="0 0 0" xyz="0 -0.00677 -0.01098" />
            <mass value="0.17" />
            <inertia ixx="9.3e-05" ixy="0.0" ixz="0.0" iyy="5.87e-05" iyz="3.6e-06" izz="0.000132" />
        </inertial>
        <visual>
            <geometry>
                <mesh filename="package://xarm_description/meshes/xarm5/visual/link5.STL" />
            </geometry>
            <origin rpy="0 0 0" xyz="0 0 0" />
            <material name="Silver" />
        </visual>
        <collision>
            <geometry>
                <mesh filename="package://xarm_description/meshes/end_tool/collision/end_tool.STL" />
            </geometry>
            <origin rpy="0 0 0" xyz="0 0 0" />
        </collision>
    </link>
    <joint name="joint5" type="revolute">
        <origin rpy="-1.5708 0 0" xyz="0.076 0.097 0" />
        <parent link="link4" />
        <child link="link5" />
        <axis xyz="0 0 1" />
        <limit effort="20" lower="-6.283185307179586" upper="6.283185307179586" velocity="3.14" />
        <dynamics damping="3" friction="1" />
    </joint>
    <!-- <link name="${prefix}link_eef" />
    <joint name="${prefix}joint_eef" type="fixed">
      <origin xyz="0 0 0" rpy="0 0 0" />
      <parent link="${prefix}link5" />
      <child link="${prefix}link_eef" />
    </joint> -->
    <transmission name="tran1">
        <type>transmission_interface/SimpleTransmission</type>
        <joint name="joint1">
            <hardwareInterface>hardware_interface/PositionJointInterface</hardwareInterface>
        </joint>
        <actuator name="motor1">
            <hardwareInterface>hardware_interface/PositionJointInterface</hardwareInterface>
            <mechanicalReduction>100</mechanicalReduction>
        </actuator>
    </transmission>
    <transmission name="tran2">
        <type>transmission_interface/SimpleTransmission</type>
        <joint name="joint2">
            <hardwareInterface>hardware_interface/PositionJointInterface</hardwareInterface>
        </joint>
        <actuator name="motor2">
            <hardwareInterface>hardware_interface/PositionJointInterface</hardwareInterface>
            <mechanicalReduction>100</mechanicalReduction>
        </actuator>
    </transmission>
    <transmission name="tran3">
        <type>transmission_interface/SimpleTransmission</type>
        <joint name="joint3">
            <hardwareInterface>hardware_interface/PositionJointInterface</hardwareInterface>
        </joint>
        <actuator name="motor3">
            <hardwareInterface>hardware_interface/PositionJointInterface</hardwareInterface>
            <mechanicalReduction>100</mechanicalReduction>
        </actuator>
    </transmission>
    <transmission name="tran4">
        <type>transmission_interface/SimpleTransmission</type>
        <joint name="joint4">
            <hardwareInterface>hardware_interface/PositionJointInterface</hardwareInterface>
        </joint>
        <actuator name="motor3">
            <hardwareInterface>hardware_interface/PositionJointInterface</hardwareInterface>
            <mechanicalReduction>100</mechanicalReduction>
        </actuator>
    </transmission>
    <transmission name="tran5">
        <type>transmission_interface/SimpleTransmission</type>
        <joint name="joint5">
            <hardwareInterface>hardware_interface/PositionJointInterface</hardwareInterface>
        </joint>
        <actuator name="motor5">
            <hardwareInterface>hardware_interface/PositionJointInterface</hardwareInterface>
            <mechanicalReduction>100</mechanicalReduction>
        </actuator>
    </transmission>
    <gazebo reference="link_base">
        <selfCollide>true</selfCollide>
        <plugin name="gazebo_ros_control">
            <robotNamespace>/</robotNamespace>
        </plugin>
    </gazebo>
    <gazebo reference="link1">
        <selfCollide>true</selfCollide>
    </gazebo>
    <gazebo reference="link2">
        <selfCollide>true</selfCollide>
    </gazebo>
    <gazebo reference="link3">
        <selfCollide>true</selfCollide>
    </gazebo>
    <gazebo reference="link4">
        <selfCollide>true</selfCollide>
    </gazebo>
    <gazebo reference="link5">
        <selfCollide>true</selfCollide>
    </gazebo>
    <link name="link_eef" />
    <joint name="joint_eef" type="fixed">
        <origin rpy="0 0 0" xyz="0 0 0" />
        <parent link="link5" />
        <child link="link_eef" />
    </joint>
    <gazebo>
        <plugin filename="libgazebo_ros_control.so" name="gazebo_ros_control">
            <robotNamespace>/xarm</robotNamespace>
            <!-- <controlPeriod>0.0001</controlPeriod> -->
            <robotSimType>gazebo_ros_control/DefaultRobotHWSim</robotSimType>
            <legacyModeNS>true</legacyModeNS>
            <!-- <preserveWorldVelocity>true</preserveWorldVelocity> -->
        </plugin>
    </gazebo>
    <!-- Insert at the end of xarm_device_macro.xacro -->
</robot>
